Workbook

Sheet daily
A1: Data | B1: 1 - Taxa de câmbio - Livre - Dólar americano (venda) - diário - u.m.c./US$ | C1: vol_3m | D1: mês | E1: quart | F1: ano | G1: EMBI | H1: média 12m EMBI | I1: EMBI centrado
A2: 37915 | B2: 2.8642 | D2: =MONTH(A2) -> 10 | E2: =IF(D2<4,3,IF(D2<7,6,IF(D2<10,9,12))) -> 12 | F2: =YEAR(A2) -> 2003 | G2: =VLOOKUP($A2, $K:$L, 2, 0) -> #N/A | I2: =G2-H2 -> #N/A | K2: 45503 | L2: 228
A3: 37916 | B3: 2.8602 | D3: =MONTH(A3) -> 10 | E3: =IF(D3<4,3,IF(D3<7,6,IF(D3<10,9,12))) -> 12 | F3: =YEAR(A3) -> 2003 | G3: =_xlfn.IFNA(VLOOKUP($A3, $K:$L, 2, 0), G2) -> #N/A | I3: =G3-H3 -> #N/A | K3: 45502 | L3: 225
A4: 37917 | B4: 2.8698 | D4: =MONTH(A4) -> 10 | E4: =IF(D4<4,3,IF(D4<7,6,IF(D4<10,9,12))) -> 12 | F4: =YEAR(A4) -> 2003 | G4: =_xlfn.IFNA(VLOOKUP($A4, $K:$L, 2, 0), G3) -> #N/A | I4: =G4-H4 -> #N/A | K4: 45499 | L4: 224
A5: 37918 | B5: 2.8695 | D5: =MONTH(A5) -> 10 | E5: =IF(D5<4,3,IF(D5<7,6,IF(D5<10,9,12))) -> 12 | F5: =YEAR(A5) -> 2003 | G5: =_xlfn.IFNA(VLOOKUP($A5, $K:$L, 2, 0), G4) -> #N/A | I5: =G5-H5 -> #N/A | K5: 45498 | L5: 226
A6: 37921 | B6: 2.8728 | D6: =MONTH(A6) -> 10 | E6: =IF(D6<4,3,IF(D6<7,6,IF(D6<10,9,12))) -> 12 | F6: =YEAR(A6) -> 2003 | G6: =_xlfn.IFNA(VLOOKUP($A6, $K:$L, 2, 0), G5) -> #N/A | I6: =G6-H6 -> #N/A | K6: 45497 | L6: 220
A7: 37922 | B7: 2.8675 | D7: =MONTH(A7) -> 10 | E7: =IF(D7<4,3,IF(D7<7,6,IF(D7<10,9,12))) -> 12 | F7: =YEAR(A7) -> 2003 | G7: =_xlfn.IFNA(VLOOKUP($A7, $K:$L, 2, 0), G6) -> #N/A | I7: =G7-H7 -> #N/A | K7: 45496 | L7: 224
A8: 37923 | B8: 2.8537 | D8: =MONTH(A8) -> 10 | E8: =IF(D8<4,3,IF(D8<7,6,IF(D8<10,9,12))) -> 12 | F8: =YEAR(A8) -> 2003 | G8: =_xlfn.IFNA(VLOOKUP($A8, $K:$L, 2, 0), G7) -> #N/A | I8: =G8-H8 -> #N/A | K8: 45495 | L8: 225
A9: 37924 | B9: 2.844 | D9: =MONTH(A9) -> 10 | E9: =IF(D9<4,3,IF(D9<7,6,IF(D9<10,9,12))) -> 12 | F9: =YEAR(A9) -> 2003 | G9: =_xlfn.IFNA(VLOOKUP($A9, $K:$L, 2, 0), G8) -> #N/A | I9: =G9-H9 -> #N/A | K9: 45492 | L9: 229
A10: 37925 | B10: 2.8562 | D10: =MONTH(A10) -> 10 | E10: =IF(D10<4,3,IF(D10<7,6,IF(D10<10,9,12))) -> 12 | F10: =YEAR(A10) -> 2003 | G10: =_xlfn.IFNA(VLOOKUP($A10, $K:$L, 2, 0), G9) -> #N/A | I10: =G10-H10 -> #N/A | K10: 45491 | L10: 232
A11: 37928 | B11: 2.8559 | D11: =MONTH(A11) -> 11 | E11: =IF(D11<4,3,IF(D11<7,6,IF(D11<10,9,12))) -> 12 | F11: =YEAR(A11) -> 2003 | G11: =_xlfn.IFNA(VLOOKUP($A11, $K:$L, 2, 0), G10) -> #N/A | I11: =G11-H11 -> #N/A | K11: 45490 | L11: 230
A12: 37929 | B12: 2.8607 | D12: =MONTH(A12) -> 11 | E12: =IF(D12<4,3,IF(D12<7,6,IF(D12<10,9,12))) -> 12 | F12: =YEAR(A12) -> 2003 | G12: =_xlfn.IFNA(VLOOKUP($A12, $K:$L, 2, 0), G11) -> #N/A | I12: =G12-H12 -> #N/A | K12: 45489 | L12: 226
A13: 37930 | B13: 2.8596 | D13: =MONTH(A13) -> 11 | E13: =IF(D13<4,3,IF(D13<7,6,IF(D13<10,9,12))) -> 12 | F13: =YEAR(A13) -> 2003 | G13: =_xlfn.IFNA(VLOOKUP($A13, $K:$L, 2, 0), G12) -> #N/A | I13: =G13-H13 -> #N/A | K13: 45488 | L13: 223
A14: 37931 | B14: 2.8708 | D14: =MONTH(A14) -> 11 | E14: =IF(D14<4,3,IF(D14<7,6,IF(D14<10,9,12))) -> 12 | F14: =YEAR(A14) -> 2003 | G14: =_xlfn.IFNA(VLOOKUP($A14, $K:$L, 2, 0), G13) -> #N/A | I14: =G14-H14 -> #N/A | K14: 45485 | L14: 224
... A18: 37937 | B18: 2.9112 | D18: =MONTH(A18) -> 11 | E18: =IF(D18<4,3,IF(D18<7,6,IF(D18<10,9,12))) -> 12 | F18: =YEAR(A18) -> 2003 | G18: =_xlfn.IFNA(VLOOKUP($A18, $K:$L, 2, 0), G17) -> #N/A | I18: =G18-H18 -> #N/A | K18: 45481 | L18: 226
A19: 37938 | B19: 2.9196 | D19: =MONTH(A19) -> 11 | E19: =IF(D19<4,3,IF(D19<7,6,IF(D19<10,9,12))) -> 12 | F19: =YEAR(A19) -> 2003 | G19: =_xlfn.IFNA(VLOOKUP($A19, $K:$L, 2, 0), G18) -> #N/A | H19: =AVERAGE(G8:G19) -> #N/A | I19: =G19-H19 -> #N/A | K19: 45478 | L19: 230
A20: 37939 | B20: 2.9418 | D20: =MONTH(A20) -> 11 | E20: =IF(D20<4,3,IF(D20<7,6,IF(D20<10,9,12))) -> 12 | F20: =YEAR(A20) -> 2003 | G20: =_xlfn.IFNA(VLOOKUP($A20, $K:$L, 2, 0), G19) -> #N/A | H20: =AVERAGE(G9:G20) -> #N/A | I20: =G20-H20 -> #N/A | K20: 45476 | L20: 235
A21: 37942 | B21: 2.9546 | D21: =MONTH(A21) -> 11 | E21: =IF(D21<4,3,IF(D21<7,6,IF(D21<10,9,12))) -> 12 | F21: =YEAR(A21) -> 2003 | G21: =_xlfn.IFNA(VLOOKUP($A21, $K:$L, 2, 0), G20) -> #N/A | H21: =AVERAGE(G10:G21) -> #N/A | I21: =G21-H21 -> #N/A | K21: 45475 | L21: 238
A22: 37943 | B22: 2.9421 | D22: =MONTH(A22) -> 11 | E22: =IF(D22<4,3,IF(D22<7,6,IF(D22<10,9,12))) -> 12 | F22: =YEAR(A22) -> 2003 | G22: =_xlfn.IFNA(VLOOKUP($A22, $K:$L, 2, 0), G21) -> #N/A | H22: =AVERAGE(G11:G22) -> #N/A | I22: =G22-H22 -> #N/A | K22: 45474 | L22: 235
A23: 37944 | B23: 2.9507 | D23: =MONTH(A23) -> 11 | E23: =IF(D23<4,3,IF(D23<7,6,IF(D23<10,9,12))) -> 12 | F23: =YEAR(A23) -> 2003 | G23: =_xlfn.IFNA(VLOOKUP($A23, $K:$L, 2, 0), G22) -> #N/A | H23: =AVERAGE(G12:G23) -> #N/A | I23: =G23-H23 -> #N/A | K23: 45471 | L23: 231
A24: 37945 | B24: 2.948 | D24: =MONTH(A24) -> 11 | E24: =IF(D24<4,3,IF(D24<7,6,IF(D24<10,9,12))) -> 12 | F24: =YEAR(A24) -> 2003 | G24: =_xlfn.IFNA(VLOOKUP($A24, $K:$L, 2, 0), G23) -> #N/A | H24: =AVERAGE(G13:G24) -> #N/A | I24: =G24-H24 -> #N/A | K24: 45470 | L24: 235
A25: 37946 | B25: 2.9301 | D25: =MONTH(A25) -> 11 | E25: =IF(D25<4,3,IF(D25<7,6,IF(D25<10,9,12))) -> 12 | F25: =YEAR(A25) -> 2003 | G25: =_xlfn.IFNA(VLOOKUP($A25, $K:$L, 2, 0), G24) -> #N/A | H25: =AVERAGE(G14:G25) -> #N/A | I25: =G25-H25 -> #N/A | K25: 45469 | L25: 233
A26: 37949 | B26: 2.927 | D26: =MONTH(A26) -> 11 | E26: =IF(D26<4,3,IF(D26<7,6,IF(D26<10,9,12))) -> 12 | F26: =YEAR(A26) -> 2003 | G26: =_xlfn.IFNA(VLOOKUP($A26, $K:$L, 2, 0), G25) -> #N/A | H26: =AVERAGE(G15:G26) -> #N/A | I26: =G26-H26 -> #N/A | K26: 45468 | L26: 235
A27: 37950 | B27: 2.9246 | D27: =MONTH(A27) -> 11 | E27: =IF(D27<4,3,IF(D27<7,6,IF(D27<10,9,12))) -> 12 | F27: =YEAR(A27) -> 2003 | G27: =_xlfn.IFNA(VLOOKUP($A27, $K:$L, 2, 0), G26) -> #N/A | H27: =AVERAGE(G16:G27) -> #N/A | I27: =G27-H27 -> #N/A | K27: 45467 | L27: 236
A28: 37951 | B28: 2.9361 | D28: =MONTH(A28) -> 11 | E28: =IF(D28<4,3,IF(D28<7,6,IF(D28<10,9,12))) -> 12 | F28: =YEAR(A28) -> 2003 | G28: =_xlfn.IFNA(VLOOKUP($A28, $K:$L, 2, 0), G27) -> #N/A | H28: =AVERAGE(G17:G28) -> #N/A | I28: =G28-H28 -> #N/A | K28: 45464 | L28: 235
A29: 37952 | B29: 2.9477 | D29: =MONTH(A29) -> 11 | E29: =IF(D29<4,3,IF(D29<7,6,IF(D29<10,9,12))) -> 12 | F29: =YEAR(A29) -> 2003 | G29: =_xlfn.IFNA(VLOOKUP($A29, $K:$L, 2, 0), G28) -> #N/A | H29: =AVERAGE(G18:G29) -> #N/A | I29: =G29-H29 -> #N/A | K29: 45463 | L29: 234
A30: 37953 | B30: 2.9494 | D30: =MONTH(A30) -> 11 | E30: =IF(D30<4,3,IF(D30<7,6,IF(D30<10,9,12))) -> 12 | F30: =YEAR(A30) -> 2003 | G30: =_xlfn.IFNA(VLOOKUP($A30, $K:$L, 2, 0), G29) -> #N/A | H30: =AVERAGE(G19:G30) -> #N/A | I30: =G30-H30 -> #N/A | K30: 45461 | L30: 235
... A61: 38000 | B61: 2.8142 | D61: =MONTH(A61) -> 1 | E61: =IF(D61<4,3,IF(D61<7,6,IF(D61<10,9,12))) -> 3 | F61: =YEAR(A61) -> 2004 | G61: =_xlfn.IFNA(VLOOKUP($A61, $K:$L, 2, 0), G60) -> #N/A | H61: =AVERAGE(G50:G61) -> #N/A | I61: =G61-H61 -> #N/A | K61: 45415 | L61: 204
A62: 38001 | B62: 2.8126 | C62: =_xlfn.STDEV.P(B1:B62) -> 0.041201636 | D62: =MONTH(A62) -> 1 | E62: =IF(D62<4,3,IF(D62<7,6,IF(D62<10,9,12))) -> 3 | F62: =YEAR(A62) -> 2004 | G62: =_xlfn.IFNA(VLOOKUP($A62, $K:$L, 2, 0), G61) -> #N/A | H62: =AVERAGE(G51:G62) -> #N/A | I62: =G62-H62 -> #N/A | K62: 45414 | L62: 208
A63: 38002 | B63: 2.8184 | C63: =_xlfn.STDEV.P(B2:B63) -> 0.042094897 | D63: =MONTH(A63) -> 1 | E63: =IF(D63<4,3,IF(D63<7,6,IF(D63<10,9,12))) -> 3 | F63: =YEAR(A63) -> 2004 | G63: =_xlfn.IFNA(VLOOKUP($A63, $K:$L, 2, 0), G62) -> #N/A | H63: =AVERAGE(G52:G63) -> #N/A | I63: =G63-H63 -> #N/A | K63: 45413 | L63: 209
A64: 38005 | B64: 2.8419 | C64: =_xlfn.STDEV.P(B3:B64) -> 0.042468908 | D64: =MONTH(A64) -> 1 | E64: =IF(D64<4,3,IF(D64<7,6,IF(D64<10,9,12))) -> 3 | F64: =YEAR(A64) -> 2004 | G64: =_xlfn.IFNA(VLOOKUP($A64, $K:$L, 2, 0), G63) -> #N/A | H64: =AVERAGE(G53:G64) -> #N/A | I64: =G64-H64 -> #N/A | K64: 45412 | L64: 210
A65: 38006 | B65: 2.8382 | C65: =_xlfn.STDEV.P(B4:B65) -> 0.042863612 | D65: =MONTH(A65) -> 1 | E65: =IF(D65<4,3,IF(D65<7,6,IF(D65<10,9,12))) -> 3 | F65: =YEAR(A65) -> 2004 | G65: =_xlfn.IFNA(VLOOKUP($A65, $K:$L, 2, 0), G64) -> #N/A | H65: =AVERAGE(G54:G65) -> #N/A | I65: =G65-H65 -> #N/A | K65: 45411 | L65: 212
A66: 38007 | B66: 2.8417 | C66: =_xlfn.STDEV.P(B5:B66) -> 0.043289786 | D66: =MONTH(A66) -> 1 | E66: =IF(D66<4,3,IF(D66<7,6,IF(D66<10,9,12))) -> 3 | F66: =YEAR(A66) -> 2004 | G66: =_xlfn.IFNA(VLOOKUP($A66, $K:$L, 2, 0), G65) -> #N/A | H66: =AVERAGE(G55:G66) -> #N/A | I66: =G66-H66 -> #N/A | K66: 45408 | L66: 212
A67: 38008 | B67: 2.8417 | C67: =_xlfn.STDEV.P(B6:B67) -> 0.043704236 | D67: =MONTH(A67) -> 1 | E67: =IF(D67<4,3,IF(D67<7,6,IF(D67<10,9,12))) -> 3 | F67: =YEAR(A67) -> 2004 | G67: =_xlfn.IFNA(VLOOKUP($A67, $K:$L, 2, 0), G66) -> #N/A | H67: =AVERAGE(G56:G67) -> #N/A | I67: =G67-H67 -> #N/A | K67: 45407 | L67: 214
A68: 38009 | B68: 2.8435 | C68: =_xlfn.STDEV.P(B7:B68) -> 0.044104591 | D68: =MONTH(A68) -> 1 | E68: =IF(D68<4,3,IF(D68<7,6,IF(D68<10,9,12))) -> 3 | F68: =YEAR(A68) -> 2004 | G68: =_xlfn.IFNA(VLOOKUP($A68, $K:$L, 2, 0), G67) -> #N/A | H68: =AVERAGE(G57:G68) -> #N/A | I68: =G68-H68 -> #N/A | K68: 45406 | L68: 214
A69: 38012 | B69: 2.8431 | C69: =_xlfn.STDEV.P(B8:B69) -> 0.04445664 | D69: =MONTH(A69) -> 1 | E69: =IF(D69<4,3,IF(D69<7,6,IF(D69<10,9,12))) -> 3 | F69: =YEAR(A69) -> 2004 | G69: =_xlfn.IFNA(VLOOKUP($A69, $K:$L, 2, 0), G68) -> #N/A | H69: =AVERAGE(G58:G69) -> #N/A | I69: =G69-H69 -> #N/A | K69: 45405 | L69: 213
A70: 38013 | B70: 2.8587 | C70: =_xlfn.STDEV.P(B9:B70) -> 0.044386646 | D70: =MONTH(A70) -> 1 | E70: =IF(D70<4,3,IF(D70<7,6,IF(D70<10,9,12))) -> 3 | F70: =YEAR(A70) -> 2004 | G70: =_xlfn.IFNA(VLOOKUP($A70, $K:$L, 2, 0), G69) -> #N/A | H70: =AVERAGE(G59:G70) -> #N/A | I70: =G70-H70 -> #N/A | K70: 45404 | L70: 215
A71: 38014 | B71: 2.8785 | C71: =_xlfn.STDEV.P(B10:B71) -> 0.043960575 | D71: =MONTH(A71) -> 1 | E71: =IF(D71<4,3,IF(D71<7,6,IF(D71<10,9,12))) -> 3 | F71: =YEAR(A71) -> 2004 | G71: =_xlfn.IFNA(VLOOKUP($A71, $K:$L, 2, 0), G70) -> #N/A | H71: =AVERAGE(G60:G71) -> #N/A | I71: =G71-H71 -> #N/A | K71: 45401 | L71: 217
A72: 38015 | B72: 2.9236 | C72: =_xlfn.STDEV.P(B11:B72) -> 0.043812071 | D72: =MONTH(A72) -> 1 | E72: =IF(D72<4,3,IF(D72<7,6,IF(D72<10,9,12))) -> 3 | F72: =YEAR(A72) -> 2004 | G72: =_xlfn.IFNA(VLOOKUP($A72, $K:$L, 2, 0), G71) -> #N/A | H72: =AVERAGE(G61:G72) -> #N/A | I72: =G72-H72 -> #N/A | K72: 45400 | L72: 218
A73: 38016 | B73: 2.9409 | C73: =_xlfn.STDEV.P(B12:B73) -> 0.043851975 | D73: =MONTH(A73) -> 1 | E73: =IF(D73<4,3,IF(D73<7,6,IF(D73<10,9,12))) -> 3 | F73: =YEAR(A73) -> 2004 | G73: =_xlfn.IFNA(VLOOKUP($A73, $K:$L, 2, 0), G72) -> #N/A | H73: =AVERAGE(G62:G73) -> #N/A | I73: =G73-H73 -> #N/A | K73: 45399 | L73: 220
...

Sheet monthly
A1: Date | B1: 433 - Broad National Consumer Price Index (IPCA) - Monthly % var. | C1: ipca_ex_sazol | D1: REER | E1: q_annual_ipca | F1: media_reer_12m | G1: REER_q centrado | H1: REER_q_vol | J1: mes | L1: sazol_tosco
A2: 37895 | B2: 0.29 | C2: =B2-VLOOKUP(J2,$K$2:$M$14, 3, 0) -> 0.24143939 | D2: 129.03 | J2: =MONTH(A2) -> 10 | L2: media_mes | M2: fator_sazol
A3: 37926 | B3: 0.34 | C3: =B3-VLOOKUP(J3,$K$2:$M$14, 3, 0) -> 0.3105303 | D3: 130.76 | J3: =MONTH(A3) -> 11 | K3: 1 | L3: =AVERAGEIFS($B:$B,$J:$J,K3) -> 0.57045455 | M3: =L3-AVERAGE($L$3:$L$14) -> 0.11219697
A4: 37956 | B4: 0.52 | C4: =B4-VLOOKUP(J4,$K$2:$M$14, 3, 0) -> 0.34143939 | D4: 133.07 | E4: =100*(((1+C4%)*(1+C3%)*(1+C2%))^4-1) -> 3.6326465 | J4: =MONTH(A4) -> 12 | K4: =K3+1 -> 2 | L4: =AVERAGEIFS($B:$B,$J:$J,K4) -> 0.66863636 | M4: =L4-AVERAGE($L$3:$L$14) -> 0.21037879
A5: 37987 | B5: 0.76 | C5: =B5-VLOOKUP(J5,$K$2:$M$14, 3, 0) -> 0.64780303 | D5: 130.93 | E5: =100*(((1+C5%)*(1+C4%)*(1+C3%))^4-1) -> 5.3233368 | J5: =MONTH(A5) -> 1 | K5: =K4+1 -> 3 | L5: =AVERAGEIFS($B:$B,$J:$J,K5) -> 0.56181818 | M5: =L5-AVERAGE($L$3:$L$14) -> 0.10356061
A6: 38018 | B6: 0.61 | C6: =B6-VLOOKUP(J6,$K$2:$M$14, 3, 0) -> 0.39962121 | D6: 137.73 | E6: =100*(((1+C6%)*(1+C5%)*(1+C4%))^4-1) -> 5.6980078 | J6: =MONTH(A6) -> 2 | K6: =K5+1 -> 4 | L6: =AVERAGEIFS($B:$B,$J:$J,K6) -> 0.48454545 | M6: =L6-AVERAGE($L$3:$L$14) -> 0.026287879
A7: 38047 | B7: 0.47 | C7: =B7-VLOOKUP(J7,$K$2:$M$14, 3, 0) -> 0.36643939 | D7: 135.51 | E7: =100*(((1+C7%)*(1+C6%)*(1+C5%))^4-1) -> 5.8033855 | J7: =MONTH(A7) -> 3 | K7: =K6+1 -> 5 | L7: =AVERAGEIFS($B:$B,$J:$J,K7) -> 0.40727273 | M7: =L7-AVERAGE($L$3:$L$14) -> -0.050984848
A8: 38078 | B8: 0.37 | C8: =B8-VLOOKUP(J8,$K$2:$M$14, 3, 0) -> 0.34371212 | D8: 135.1 | E8: =100*(((1+C8%)*(1+C7%)*(1+C6%))^4-1) -> 4.5304981 | J8: =MONTH(A8) -> 4 | K8: =K7+1 -> 6 | L8: =AVERAGEIFS($B:$B,$J:$J,K8) -> 0.30727273 | M8: =L8-AVERAGE($L$3:$L$14) -> -0.15098485
A9: 38108 | B9: 0.51 | C9: =B9-VLOOKUP(J9,$K$2:$M$14, 3, 0) -> 0.56098485 | D9: 142.57 | E9: =100*(((1+C9%)*(1+C8%)*(1+C7%))^4-1) -> 5.2041313 | J9: =MONTH(A9) -> 5 | K9: =K8+1 -> 7 | L9: =AVERAGEIFS($B:$B,$J:$J,K9) -> 0.28636364 | M9: =L9-AVERAGE($L$3:$L$14) -> -0.17189394
A10: 38139 | B10: 0.71 | C10: =B10-VLOOKUP(J10,$K$2:$M$14, 3, 0) -> 0.86098485 | D10: 144.1 | E10: =100*(((1+C10%)*(1+C9%)*(1+C8%))^4-1) -> 7.2930381 | J10: =MONTH(A10) -> 6 | K10: =K9+1 -> 8 | L10: =AVERAGEIFS($B:$B,$J:$J,K10) -> 0.22 | M10: =L10-AVERAGE($L$3:$L$14) -> -0.23825758
A11: 38169 | B11: 0.91 | C11: =B11-VLOOKUP(J11,$K$2:$M$14, 3, 0) -> 1.0818939 | D11: 139.4 | E11: =100*(((1+C11%)*(1+C10%)*(1+C9%))^4-1) -> 10.485268 | J11: =MONTH(A11) -> 7 | K11: =K10+1 -> 9 | L11: =AVERAGEIFS($B:$B,$J:$J,K11) -> 0.36136364 | M11: =L11-AVERAGE($L$3:$L$14) -> -0.096893939
A12: 38200 | B12: 0.69 | C12: =B12-VLOOKUP(J12,$K$2:$M$14, 3, 0) -> 0.92825758 | D12: 136.65 | E12: =100*(((1+C12%)*(1+C11%)*(1+C10%))^4-1) -> 12.108206 | J12: =MONTH(A12) -> 8 | K12: =K11+1 -> 10 | L12: =AVERAGEIFS($B:$B,$J:$J,K12) -> 0.50681818 | M12: =L12-AVERAGE($L$3:$L$14) -> 0.048560606
A13: 38231 | B13: 0.33 | C13: =B13-VLOOKUP(J13,$K$2:$M$14, 3, 0) -> 0.42689394 | D13: 131.58 | E13: =100*(((1+C13%)*(1+C12%)*(1+C11%))^4-1) -> 10.190641 | F13: =AVERAGE(D2:D13) -> 135.53583 | G13: =100*(AVERAGE(D11:D13)/F13-1) -> 0.25147101 | H13: =_xlfn.STDEV.P(D11:D13)-1.9364277 -> 1.3025673 | J13: =MONTH(A13) -> 9 | K13: =K12+1 -> 11 | L13: =AVERAGEIFS($B:$B,$J:$J,K13) -> 0.48772727 | M13: =L13-AVERAGE($L$3:$L$14) -> 0.029469697
A14: 38261 | B14: 0.44 | C14: =B14-VLOOKUP(J14,$K$2:$M$14, 3, 0) -> 0.39143939 | D14: 130.98 | E14: =100*(((1+C14%)*(1+C13%)*(1+C12%))^4-1) -> 7.2106552 | F14: =AVERAGE(D3:D14) -> 135.69833 | G14: =100*(AVERAGE(D12:D14)/F14-1) -> -1.9368943 | H14: =_xlfn.STDEV.P(D12:D14)-1.9364277 -> 0.60683792 | J14: =MONTH(A14) -> 10 | K14: =K13+1 -> 12 | L14: =AVERAGEIFS($B:$B,$J:$J,K14) -> 0.63681818 | M14: =L14-AVERAGE($L$3:$L$14) -> 0.17856061
A15: 38292 | B15: 0.69 | C15: =B15-VLOOKUP(J15,$K$2:$M$14, 3, 0) -> 0.6605303 | D15: 129.05 | E15: =100*(((1+C15%)*(1+C14%)*(1+C13%))^4-1) -> 6.0776045 | F15: =AVERAGE(D4:D15) -> 135.55583 | G15: =100*(AVERAGE(D13:D15)/F15-1) -> -3.7026563 | H15: =_xlfn.STDEV.P(D13:D15)-1.9364277 -> -0.85703487 | J15: =MONTH(A15) -> 11
A16: 38322 | B16: 0.86 | C16: =B16-VLOOKUP(J16,$K$2:$M$14, 3, 0) -> 0.68143939 | D16: 126.88 | E16: =100*(((1+C16%)*(1+C15%)*(1+C14%))^4-1) -> 7.1571721 | F16: =AVERAGE(D5:D16) -> 135.04 | G16: =100*(AVERAGE(D14:D16)/F16-1) -> -4.4949645 | H16: =_xlfn.STDEV.P(D14:D16)-1.9364277 -> -0.26165408 | J16: =MONTH(A16) -> 12
A17: 38353 | B17: 0.58 | C17: =B17-VLOOKUP(J17,$K$2:$M$14, 3, 0) -> 0.46780303 | D17: 124.02 | E17: =100*(((1+C17%)*(1+C16%)*(1+C15%))^4-1) -> 7.4835845 | F17: =AVERAGE(D6:D17) -> 134.46417 | G17: =100*(AVERAGE(D15:D17)/F17-1) -> -5.8113376 | H17: =_xlfn.STDEV.P(D15:D17)-1.9364277 -> 0.12349139 | J17: =MONTH(A17) -> 1
A18: 38384 | B18: 0.59 | C18: =B18-VLOOKUP(J18,$K$2:$M$14, 3, 0) -> 0.37962121 | D18: 120.05 | E18: =100*(((1+C18%)*(1+C17%)*(1+C16%))^4-1) -> 6.2887979 | F18: =AVERAGE(D7:D18) -> 132.99083 | G18: =100*(AVERAGE(D16:D18)/F18-1) -> -7.023667 | H18: =_xlfn.STDEV.P(D16:D18)-1.9364277 -> 0.86415557 | J18: =MONTH(A18) -> 2
A19: 38412 | B19: 0.61 | C19: =B19-VLOOKUP(J19,$K$2:$M$14, 3, 0) -> 0.50643939 | D19: 125.3 | E19: =100*(((1+C19%)*(1+C18%)*(1+C17%))^4-1) -> 5.5517365 | F19: =AVERAGE(D8:D19) -> 132.14 | G19: =100*(AVERAGE(D17:D19)/F19-1) -> -6.823571 | H19: =_xlfn.STDEV.P(D17:D19)-1.9364277 -> 0.29869099 | J19: =MONTH(A19) -> 3
A20: 38443 | B20: 0.87 | C20: =B20-VLOOKUP(J20,$K$2:$M$14, 3, 0) -> 0.84371212 | D20: 118.26 | E20: =100*(((1+C20%)*(1+C19%)*(1+C18%))^4-1) -> 7.140349 | F20: =AVERAGE(D9:D20) -> 130.73667 | G20: =100*(AVERAGE(D18:D20)/F20-1) -> -7.2920119 | H20: =_xlfn.STDEV.P(D18:D20)-1.9364277 -> 1.0511057 | J20: =MONTH(A20) -> 4
A21: 38473 | B21: 0.49 | C21: =B21-VLOOKUP(J21,$K$2:$M$14, 3, 0) -> 0.54098485 | D21: 111.64 | E21: =100*(((1+C21%)*(1+C20%)*(1+C19%))^4-1) -> 7.8309389 | F21: =AVERAGE(D10:D21) -> 128.15917 | G21: =100*(AVERAGE(D19:D21)/F21-1) -> -7.6148799 | H21: =_xlfn.STDEV.P(D19:D21)-1.9364277 -> 3.6411225 | J21: =MONTH(A21) -> 5
A22: 38504 | B22: -0.02 | C22: =B22-VLOOKUP(J22,$K$2:$M$14, 3, 0) -> 0.13098485 | D22: 108.35 | E22: =100*(((1+C22%)*(1+C21%)*(1+C20%))^4-1) -> 6.2286805 | F22: =AVERAGE(D11:D22) -> 125.18 | G22: =100*(AVERAGE(D20:D22)/F22-1) -> -9.9297012 | H22: =_xlfn.STDEV.P(D20:D22)-1.9364277 -> 2.1847453 | J22: =MONTH(A22) -> 6
A23: 38534 | B23: 0.25 | C23: =B23-VLOOKUP(J23,$K$2:$M$14, 3, 0) -> 0.42189394 | D23: 106.38 | E23: =100*(((1+C23%)*(1+C22%)*(1+C21%))^4-1) -> 4.4624296 | F23: =AVERAGE(D12:D23) -> 122.42833 | G23: =100*(AVERAGE(D21:D23)/F23-1) -> -11.139851 | H23: =_xlfn.STDEV.P(D21:D23)-1.9364277 -> 0.23338028 | J23: =MONTH(A23) -> 7
A24: 38565 | B24: 0.17 | C24: =B24-VLOOKUP(J24,$K$2:$M$14, 3, 0) -> 0.40825758 | D24: 106.82 | E24: =100*(((1+C24%)*(1+C23%)*(1+C22%))^4-1) -> 3.9119046 | F24: =AVERAGE(D13:D24) -> 119.9425 | G24: =100*(AVERAGE(D22:D24)/F24-1) -> -10.637736 | H24: =_xlfn.STDEV.P(D22:D24)-1.9364277 -> -1.0921397 | J24: =MONTH(A24) -> 8
A25: 38596 | B25: 0.35 | C25: =B25-VLOOKUP(J25,$K$2:$M$14, 3, 0) -> 0.44689394 | D25: 104.03 | E25: =100*(((1+C25%)*(1+C24%)*(1+C23%))^4-1) -> 5.2294745 | F25: =AVERAGE(D14:D25) -> 117.64667 | G25: =100*(AVERAGE(D23:D25)/F25-1) -> -10.117867 | H25: =_xlfn.STDEV.P(D23:D25)-1.9364277 -> -0.71167376 | J25: =MONTH(A25) -> 9
A26: 38626 | B26: 0.75 | C26: =B26-VLOOKUP(J26,$K$2:$M$14, 3, 0) -> 0.70143939 | D26: 100.88 | E26: =100*(((1+C26%)*(1+C25%)*(1+C24%))^4-1) -> 6.4060896 | F26: =AVERAGE(D15:D26) -> 115.13833 | G26: =100*(AVERAGE(D24:D26)/F26-1) -> -9.7520374 | H26: =_xlfn.STDEV.P(D24:D26)-1.9364277 -> 0.49005123 | J26: =MONTH(A26) -> 10
... A263: 45839 | B263: 0.26 | C263: =B263-VLOOKUP(J263,$K$2:$M$14, 3, 0) -> 0.43189394 | D263: 128.83 | E263: =100*(((1+C263%)*(1+C262%)*(1+C261%))^4-1) -> 4.6307761 | F263: =AVERAGE(D252:D263) -> 132.72417 | G263: =100*(AVERAGE(D261:D263)/F263-1) -> -2.8888233 | H263: =_xlfn.STDEV.P(D261:D263)-1.9364277 -> -1.0943667 | J263: =MONTH(A263) -> 7
A264: 45870 | B264: -0.11 | C264: =B264-VLOOKUP(J264,$K$2:$M$14, 3, 0) -> 0.12825758 | D264: - | E264: =100*(((1+C264%)*(1+C263%)*(1+C262%))^4-1) -> 3.8704718 | F264: =AVERAGE(D253:D264) -> 132.58182 | G264: =100*(AVERAGE(D262:D264)/F264-1) -> -3.1843116 | H264: =_xlfn.STDEV.P(D262:D264)-1.9364277 -> -1.4664277 | J264: =MONTH(A264) -> 8
A265: 45901 | B265: 0.48 | C265: =B265-VLOOKUP(J265,$K$2:$M$14, 3, 0) -> 0.57689394 | D265: - | E265: =100*(((1+C265%)*(1+C264%)*(1+C263%))^4-1) -> 4.642022 | F265: =AVERAGE(D254:D265) -> 132.47 | G265: =100*(AVERAGE(D263:D265)/F265-1) -> -2.747792 | H265: =_xlfn.STDEV.P(D263:D265)-1.9364277 -> -1.9364277 | J265: =MONTH(A265) -> 9
A266: Source | B266: IBGE | C266: =B266-VLOOKUP(J266,$K$2:$M$14, 3, 0) -> #VALUE! | D266: BCB-DSTAT

Sheet quart
A1: Date | B1: 22109 - Quarterly GDP - seasonally adjusted data - GDP at market prices - Index | C1: hiato_bcb | D1: fedfunds_fred | E1: hiato_bcb_2 | F1: fed_hlw_neutral
A2: 37956 | B2: 118.75 | C2: -1.1 | D2: 1 | E2: -0.99 | F2: 2.7416469
A3: =EDATE(A2, 3) -> 38047 | B3: 120.5 | C3: -0.63 | D3: 1 | E3: -0.54 | F3: 2.6593216
A4: =EDATE(A3, 3) -> 38139 | B4: 123.74 | C4: -0.21 | D4: 1.01 | E4: -0.11 | F4: 2.6418991
A5: =EDATE(A4, 3) -> 38231 | B5: 125.33 | C5: 0.19 | D5: 1.43 | E5: 0.27 | F5: 2.5583776
A6: =EDATE(A5, 3) -> 38322 | B6: 126.32 | C6: 0.46 | D6: 1.95 | E6: 0.49 | F6: 2.6214573
A7: =EDATE(A6, 3) -> 38412 | B7: 127.37 | C7: 0.47 | D7: 2.47 | E7: 0.46 | F7: 2.7318235
A8: =EDATE(A7, 3) -> 38504 | B8: 128.72 | C8: 0.06 | D8: 2.94 | E8: 0.11 | F8: 2.5625561
A9: =EDATE(A8, 3) -> 38596 | B9: 128.06 | C9: -0.34 | D9: 3.46 | E9: -0.25 | F9: 2.517547
A10: =EDATE(A9, 3) -> 38687 | B10: 129.73 | C10: -0.4 | D10: 3.98 | E10: -0.36 | F10: 2.5681201
A11: =EDATE(A10, 3) -> 38777 | B11: 131.62 | C11: -0.34 | D11: 4.46 | E11: -0.34 | F11: 2.7092277
A12: =EDATE(A11, 3) -> 38869 | B12: 132.16 | C12: -0.3 | D12: 4.91 | E12: -0.29 | F12: 2.6830138
A13: =EDATE(A12, 3) -> 38961 | B13: 134.38 | C13: -0.15 | D13: 5.25 | E13: -0.13 | F13: 2.5169382
A14: =EDATE(A13, 3) -> 39052 | B14: 136.01 | C14: 0.01 | D14: 5.25 | E14: 0.04 | F14: 2.5506084
... A84: =EDATE(A83, 3) -> 45444 | B84: 189.49 | C84: 0.01 | D84: 5.33 | E84: 0.85 | F84: 0.85779552
A85: =EDATE(A84, 3) -> 45536 | B85: 190.99 | D85: 5.26 | E85: 1.02 | F85: 0.81923691
A86: =EDATE(A85, 3) -> 45627 | B86: 191.11 | D86: 4.65 | E86: 1.03 | F86: 0.8258027
A87: =EDATE(A86, 3) -> 45717 | B87: 193.61 | D87: 4.33 | E87: 0.86 | F87: 0.79233319
A88: =EDATE(A87, 3) -> 45809 | B88: 194.33 | D88: 4.33 | E88: 0.5 | F88: 0.83983803
A89: =EDATE(A88, 3) -> 45901 | B89: IBGE | D89: 4.29

Sheet annual
A1: Date | B1: 13521 - Target inflation rate - %
A2: 2003 | B2: 4
A3: 2004 | B3: 5.5
A4: 2005 | B4: 4.5
A5: 2006 | B5: 4.5
A6: 2007 | B6: 4.5
A7: 2008 | B7: 4.5
A8: 2009 | B8: 4.5
A9: 2010 | B9: 4.5
A10: 2011 | B10: 4.5
A11: 2012 | B11: 4.5
A12: 2013 | B12: 4.5
A13: 2014 | B13: 4.5
... A24: 2025 | B24: 3
A25: Source | B25: BCB-Depec

Sheet focus_ipca
A1: IPCA - variação % - Mediana - Período de 21/09/2006 a 21/09/2016 - Base: Expectativas informadas nos últimos 30 dias | D1: mês | E1: quart | F1: ano
B2: Infl. 12 m | C2: Infl. 12 m suav.
A3: 38981 | B3: 4.08 | C3: 4.15 | D3: =MONTH(A3) -> 9 | E3: =IF(D3<4,3,IF(D3<7,6,IF(D3<10,9,12))) -> 9 | F3: =YEAR(A3) -> 2006
A4: 38982 | B4: 4.01 | C4: 4.13 | D4: =MONTH(A4) -> 9 | E4: =IF(D4<4,3,IF(D4<7,6,IF(D4<10,9,12))) -> 9 | F4: =YEAR(A4) -> 2006
A5: 38985 | B5: 4.02 | C5: 4.16 | D5: =MONTH(A5) -> 9 | E5: =IF(D5<4,3,IF(D5<7,6,IF(D5<10,9,12))) -> 9 | F5: =YEAR(A5) -> 2006
A6: 38986 | B6: 3.98 | C6: 4.13 | D6: =MONTH(A6) -> 9 | E6: =IF(D6<4,3,IF(D6<7,6,IF(D6<10,9,12))) -> 9 | F6: =YEAR(A6) -> 2006
A7: 38987 | B7: 3.98 | C7: 4.11 | D7: =MONTH(A7) -> 9 | E7: =IF(D7<4,3,IF(D7<7,6,IF(D7<10,9,12))) -> 9 | F7: =YEAR(A7) -> 2006
A8: 38988 | B8: 3.96 | C8: 4.12 | D8: =MONTH(A8) -> 9 | E8: =IF(D8<4,3,IF(D8<7,6,IF(D8<10,9,12))) -> 9 | F8: =YEAR(A8) -> 2006
A9: 38989 | B9: 3.95 | C9: 4.1 | D9: =MONTH(A9) -> 9 | E9: =IF(D9<4,3,IF(D9<7,6,IF(D9<10,9,12))) -> 9 | F9: =YEAR(A9) -> 2006
A10: 38992 | B10: 3.94 | C10: 4.11 | D10: =MONTH(A10) -> 10 | E10: =IF(D10<4,3,IF(D10<7,6,IF(D10<10,9,12))) -> 12 | F10: =YEAR(A10) -> 2006
A11: 38993 | B11: 3.92 | C11: 4.11 | D11: =MONTH(A11) -> 10 | E11: =IF(D11<4,3,IF(D11<7,6,IF(D11<10,9,12))) -> 12 | F11: =YEAR(A11) -> 2006
A12: 38994 | B12: 3.9 | C12: 4.08 | D12: =MONTH(A12) -> 10 | E12: =IF(D12<4,3,IF(D12<7,6,IF(D12<10,9,12))) -> 12 | F12: =YEAR(A12) -> 2006
A13: 38995 | B13: 3.9 | C13: 4.08 | D13: =MONTH(A13) -> 10 | E13: =IF(D13<4,3,IF(D13<7,6,IF(D13<10,9,12))) -> 12 | F13: =YEAR(A13) -> 2006
A14: 38996 | B14: 4.08 | C14: 4.08 | D14: =MONTH(A14) -> 10 | E14: =IF(D14<4,3,IF(D14<7,6,IF(D14<10,9,12))) -> 12 | F14: =YEAR(A14) -> 2006
... A4792: 45947 | B4792: 4.089 | C4792: 4.12 | D4792: =MONTH(A4792) -> 10 | E4792: =IF(D4792<4,3,IF(D4792<7,6,IF(D4792<10,9,12))) -> 12 | F4792: =YEAR(A4792) -> 2025
D4793: =MONTH(A4793) -> 1 | E4793: =IF(D4793<4,3,IF(D4793<7,6,IF(D4793<10,9,12))) -> 3 | F4793: =YEAR(A4793) -> 1900
D4794: =MONTH(A4794) -> 1 | E4794: =IF(D4794<4,3,IF(D4794<7,6,IF(D4794<10,9,12))) -> 3 | F4794: =YEAR(A4794) -> 1900
D4795: =MONTH(A4795) -> 1 | E4795: =IF(D4795<4,3,IF(D4795<7,6,IF(D4795<10,9,12))) -> 3 | F4795: =YEAR(A4795) -> 1900
D4796: =MONTH(A4796) -> 1 | E4796: =IF(D4796<4,3,IF(D4796<7,6,IF(D4796<10,9,12))) -> 3 | F4796: =YEAR(A4796) -> 1900
D4797: =MONTH(A4797) -> 1 | E4797: =IF(D4797<4,3,IF(D4797<7,6,IF(D4797<10,9,12))) -> 3 | F4797: =YEAR(A4797) -> 1900
D4798: =MONTH(A4798) -> 1 | E4798: =IF(D4798<4,3,IF(D4798<7,6,IF(D4798<10,9,12))) -> 3 | F4798: =YEAR(A4798) -> 1900
D4799: =MONTH(A4799) -> 1 | E4799: =IF(D4799<4,3,IF(D4799<7,6,IF(D4799<10,9,12))) -> 3 | F4799: =YEAR(A4799) -> 1900
D4800: =MONTH(A4800) -> 1 | E4800: =IF(D4800<4,3,IF(D4800<7,6,IF(D4800<10,9,12))) -> 3 | F4800: =YEAR(A4800) -> 1900
D4801: =MONTH(A4801) -> 1 | E4801: =IF(D4801<4,3,IF(D4801<7,6,IF(D4801<10,9,12))) -> 3 | F4801: =YEAR(A4801) -> 1900
D4802: =MONTH(A4802) -> 1 | E4802: =IF(D4802<4,3,IF(D4802<7,6,IF(D4802<10,9,12))) -> 3 | F4802: =YEAR(A4802) -> 1900
D4803: =MONTH(A4803) -> 1 | E4803: =IF(D4803<4,3,IF(D4803<7,6,IF(D4803<10,9,12))) -> 3 | F4803: =YEAR(A4803) -> 1900
D4804: =MONTH(A4804) -> 1 | E4804: =IF(D4804<4,3,IF(D4804<7,6,IF(D4804<10,9,12))) -> 3 | F4804: =YEAR(A4804) -> 1900
... D5528: =MONTH(A5528) -> 1 | E5528: =IF(D5528<4,3,IF(D5528<7,6,IF(D5528<10,9,12))) -> 3 | F5528: =YEAR(A5528) -> 1900

Sheet focus_primary
A1: Resultado primário - % do PIB - Mediana - Período de 21/09/2006 a 21/09/2016 - Base: Expectativas informadas nos últimos 30 dias
A2: Data | B2: 2006 | C2: 2007 | D2: 2008 | E2: 2009 | F2: 2010 | G2: 2011 | H2: 2012 | I2: 2013 | J2: 2014 | K2: 2015 | L2: 2016 | M2: 2017 | N2: 2018 | O2: 2019 | P2: 2020 | Q2: =P2+1 -> 2021 | R2: =Q2+1 -> 2022 | S2: =R2+1 -> 2023 | T2: =S2+1 -> 2024 | U2: =T2+1 -> 2025 | V2: =U2+1 -> 2026 | W2: =V2+1 -> 2027 | X2: =W2+1 -> 2028 | ... AD2: =AC2+1 -> 2034
A3: 38981 | B3: 4.25 | C3: 4.25 | D3: 4.25 | E3: 4.25 | F3: 4
A4: 38982 | B4: 4.25 | C4: 4.25 | D4: 4.25 | E4: 4.25 | F4: 4
A5: 38985 | B5: 4.25 | C5: 4.25 | D5: 4.25 | E5: 4.25 | F5: 4
A6: 38986 | B6: 4.25 | C6: 4.25 | D6: 4.25 | E6: 4.25 | F6: 4
A7: 38987 | B7: 4.25 | C7: 4.25 | D7: 4.25 | E7: 4.25 | F7: 4
A8: 38988 | B8: 4.25 | C8: 4.25 | D8: 4.25 | E8: 4.25 | F8: 4
A9: 38989 | B9: 4.25 | C9: 4.25 | D9: 4.25 | E9: 4.25 | F9: 4
A10: 38992 | B10: 4.25 | C10: 4.25 | D10: 4.25 | E10: 4.25 | F10: 4.1
A11: 38993 | B11: 4.25 | C11: 4.25 | D11: 4.25 | E11: 4.25 | F11: 4.1
A12: 38994 | B12: 4.25 | C12: 4.25 | D12: 4.25 | E12: 4.25 | F12: 4.1
A13: 38995 | B13: 4.25 | C13: 4.25 | D13: 4.25 | E13: 4.25 | F13: 4.2
A14: 38996 | B14: 4.25 | C14: 4.25 | D14: 4.25 | E14: 4.25 | F14: 4.2
... A91: 39112 | B91: 4.25 | C91: 4.1 | D91: 4 | E91: 4 | F91: 4
A92: 39113 | C92: 4.1 | D92: 4 | E92: 4 | F92: 4 | G92: 3.88
A93: 39114 | C93: 4.1 | D93: 4 | E93: 4 | F93: 4 | G93: 4
A94: 39115 | C94: 4 | D94: 4 | E94: 4 | F94: 4 | G94: 4
A95: 39118 | C95: 4 | D95: 4 | E95: 4 | F95: 3.9 | G95: 3.88
A96: 39119 | C96: 4 | D96: 4 | E96: 4 | F96: 3.9 | G96: 3.75
A97: 39120 | C97: 4 | D97: 4 | E97: 4 | F97: 3.95 | G97: 3.88
A98: 39121 | C98: 4 | D98: 4 | E98: 4 | F98: 3.9 | G98: 3.88
A99: 39122 | C99: 4 | D99: 4 | E99: 4 | F99: 3.95 | G99: 3.88
A100: 39125 | C100: 4 | D100: 3.95 | E100: 4 | F100: 3.85 | G100: 3.78
A101: 39126 | C101: 4 | D101: 3.9 | E101: 4 | F101: 3.85 | G101: 3.78
A102: 39127 | C102: 4 | D102: 3.9 | E102: 3.95 | F102: 3.8 | G102: 3.78
A103: 39128 | C103: 4 | D103: 3.9 | E103: 3.95 | F103: 3.8 | G103: 3.78
... A340: 39476 | C340: 4 | D340: 3.6 | E340: 3.5 | F340: 3.5 | G340: 3.4
A341: 39477 | D341: 3.6 | E341: 3.5 | F341: 3.5 | G341: 3.4
A342: 39478 | D342: 3.63 | E342: 3.5 | F342: 3.5 | G342: 3.43 | H342: 3
A343: 39479 | D343: 3.6 | E343: 3.5 | F343: 3.5 | G343: 3.4 | H343: 3.2
A344: 39484 | D344: 3.6 | E344: 3.5 | F344: 3.5 | G344: 3.4 | H344: 3.35
A345: 39485 | D345: 3.63 | E345: 3.5 | F345: 3.5 | G345: 3.43 | H345: 3.35
A346: 39486 | D346: 3.66 | E346: 3.5 | F346: 3.5 | G346: 3.4 | H346: 3.35
A347: 39489 | D347: 3.68 | E347: 3.5 | F347: 3.5 | G347: 3.43 | H347: 3.5
A348: 39490 | D348: 3.68 | E348: 3.5 | F348: 3.5 | G348: 3.43 | H348: 3.4
A349: 39491 | D349: 3.7 | E349: 3.5 | F349: 3.5 | G349: 3.4 | H349: 3.4
A350: 39492 | D350: 3.7 | E350: 3.5 | F350: 3.5 | G350: 3.4 | H350: 3.4
A351: 39493 | D351: 3.7 | E351: 3.5 | F351: 3.5 | G351: 3.43 | H351: 3.4
A352: 39496 | D352: 3.7 | E352: 3.5 | F352: 3.5 | G352: 3.4 | H352: 3.34
...

Sheet fiscal_1_y_a
B1: surplus_ano_corrente | C1: surplus_ano_seguinte | D1: surplus_1ya | E1: month | F1: quart | G1: year
A2: =focus_primary!A3 -> 38981 | B2: =VLOOKUP($A2, focus_primary!$A:$AQ, MATCH(YEAR(fiscal_1_y_a!A2), focus_primary!$2:$2, 0), 0) -> 4.25 | C2: =VLOOKUP($A2, focus_primary!$A:$AQ, MATCH(YEAR(A2)+1, focus_primary!$2:$2, 0), 0) -> 4.25 | D2: =(B2*(12-MONTH(A2))+C2*MONTH(A2))/12 -> 4.25 | E2: =MONTH(A2) -> 9 | F2: =IF(E2<4,3,IF(E2<7,6,IF(E2<10,9,12))) -> 9 | G2: =YEAR(A2) -> 2006
A3: =focus_primary!A4 -> 38982 | B3: =VLOOKUP($A3, focus_primary!$A:$AQ, MATCH(YEAR(fiscal_1_y_a!A3), focus_primary!$2:$2, 0), 0) -> 4.25 | C3: =VLOOKUP($A3, focus_primary!$A:$AQ, MATCH(YEAR(A3)+1, focus_primary!$2:$2, 0), 0) -> 4.25 | D3: =(B3*(12-MONTH(A3))+C3*MONTH(A3))/12 -> 4.25 | E3: =MONTH(A3) -> 9 | F3: =IF(E3<4,3,IF(E3<7,6,IF(E3<10,9,12))) -> 9 | G3: =YEAR(A3) -> 2006
A4: =focus_primary!A5 -> 38985 | B4: =VLOOKUP($A4, focus_primary!$A:$AQ, MATCH(YEAR(fiscal_1_y_a!A4), focus_primary!$2:$2, 0), 0) -> 4.25 | C4: =VLOOKUP($A4, focus_primary!$A:$AQ, MATCH(YEAR(A4)+1, focus_primary!$2:$2, 0), 0) -> 4.25 | D4: =(B4*(12-MONTH(A4))+C4*MONTH(A4))/12 -> 4.25 | E4: =MONTH(A4) -> 9 | F4: =IF(E4<4,3,IF(E4<7,6,IF(E4<10,9,12))) -> 9 | G4: =YEAR(A4) -> 2006
A5: =focus_primary!A6 -> 38986 | B5: =VLOOKUP($A5, focus_primary!$A:$AQ, MATCH(YEAR(fiscal_1_y_a!A5), focus_primary!$2:$2, 0), 0) -> 4.25 | C5: =VLOOKUP($A5, focus_primary!$A:$AQ, MATCH(YEAR(A5)+1, focus_primary!$2:$2, 0), 0) -> 4.25 | D5: =(B5*(12-MONTH(A5))+C5*MONTH(A5))/12 -> 4.25 | E5: =MONTH(A5) -> 9 | F5: =IF(E5<4,3,IF(E5<7,6,IF(E5<10,9,12))) -> 9 | G5: =YEAR(A5) -> 2006
A6: =focus_primary!A7 -> 38987 | B6: =VLOOKUP($A6, focus_primary!$A:$AQ, MATCH(YEAR(fiscal_1_y_a!A6), focus_primary!$2:$2, 0), 0) -> 4.25 | C6: =VLOOKUP($A6, focus_primary!$A:$AQ, MATCH(YEAR(A6)+1, focus_primary!$2:$2, 0), 0) -> 4.25 | D6: =(B6*(12-MONTH(A6))+C6*MONTH(A6))/12 -> 4.25 | E6: =MONTH(A6) -> 9 | F6: =IF(E6<4,3,IF(E6<7,6,IF(E6<10,9,12))) -> 9 | G6: =YEAR(A6) -> 2006
A7: =focus_primary!A8 -> 38988 | B7: =VLOOKUP($A7, focus_primary!$A:$AQ, MATCH(YEAR(fiscal_1_y_a!A7), focus_primary!$2:$2, 0), 0) -> 4.25 | C7: =VLOOKUP($A7, focus_primary!$A:$AQ, MATCH(YEAR(A7)+1, focus_primary!$2:$2, 0), 0) -> 4.25 | D7: =(B7*(12-MONTH(A7))+C7*MONTH(A7))/12 -> 4.25 | E7: =MONTH(A7) -> 9 | F7: =IF(E7<4,3,IF(E7<7,6,IF(E7<10,9,12))) -> 9 | G7: =YEAR(A7) -> 2006
A8: =focus_primary!A9 -> 38989 | B8: =VLOOKUP($A8, focus_primary!$A:$AQ, MATCH(YEAR(fiscal_1_y_a!A8), focus_primary!$2:$2, 0), 0) -> 4.25 | C8: =VLOOKUP($A8, focus_primary!$A:$AQ, MATCH(YEAR(A8)+1, focus_primary!$2:$2, 0), 0) -> 4.25 | D8: =(B8*(12-MONTH(A8))+C8*MONTH(A8))/12 -> 4.25 | E8: =MONTH(A8) -> 9 | F8: =IF(E8<4,3,IF(E8<7,6,IF(E8<10,9,12))) -> 9 | G8: =YEAR(A8) -> 2006
A9: =focus_primary!A10 -> 38992 | B9: =VLOOKUP($A9, focus_primary!$A:$AQ, MATCH(YEAR(fiscal_1_y_a!A9), focus_primary!$2:$2, 0), 0) -> 4.25 | C9: =VLOOKUP($A9, focus_primary!$A:$AQ, MATCH(YEAR(A9)+1, focus_primary!$2:$2, 0), 0) -> 4.25 | D9: =(B9*(12-MONTH(A9))+C9*MONTH(A9))/12 -> 4.25 | E9: =MONTH(A9) -> 10 | F9: =IF(E9<4,3,IF(E9<7,6,IF(E9<10,9,12))) -> 12 | G9: =YEAR(A9) -> 2006
A10: =focus_primary!A11 -> 38993 | B10: =VLOOKUP($A10, focus_primary!$A:$AQ, MATCH(YEAR(fiscal_1_y_a!A10), focus_primary!$2:$2, 0), 0) -> 4.25 | C10: =VLOOKUP($A10, focus_primary!$A:$AQ, MATCH(YEAR(A10)+1, focus_primary!$2:$2, 0), 0) -> 4.25 | D10: =(B10*(12-MONTH(A10))+C10*MONTH(A10))/12 -> 4.25 | E10: =MONTH(A10) -> 10 | F10: =IF(E10<4,3,IF(E10<7,6,IF(E10<10,9,12))) -> 12 | G10: =YEAR(A10) -> 2006
A11: =focus_primary!A12 -> 38994 | B11: =VLOOKUP($A11, focus_primary!$A:$AQ, MATCH(YEAR(fiscal_1_y_a!A11), focus_primary!$2:$2, 0), 0) -> 4.25 | C11: =VLOOKUP($A11, focus_primary!$A:$AQ, MATCH(YEAR(A11)+1, focus_primary!$2:$2, 0), 0) -> 4.25 | D11: =(B11*(12-MONTH(A11))+C11*MONTH(A11))/12 -> 4.25 | E11: =MONTH(A11) -> 10 | F11: =IF(E11<4,3,IF(E11<7,6,IF(E11<10,9,12))) -> 12 | G11: =YEAR(A11) -> 2006
A12: =focus_primary!A13 -> 38995 | B12: =VLOOKUP($A12, focus_primary!$A:$AQ, MATCH(YEAR(fiscal_1_y_a!A12), focus_primary!$2:$2, 0), 0) -> 4.25 | C12: =VLOOKUP($A12, focus_primary!$A:$AQ, MATCH(YEAR(A12)+1, focus_primary!$2:$2, 0), 0) -> 4.25 | D12: =(B12*(12-MONTH(A12))+C12*MONTH(A12))/12 -> 4.25 | E12: =MONTH(A12) -> 10 | F12: =IF(E12<4,3,IF(E12<7,6,IF(E12<10,9,12))) -> 12 | G12: =YEAR(A12) -> 2006
A13: =focus_primary!A14 -> 38996 | B13: =VLOOKUP($A13, focus_primary!$A:$AQ, MATCH(YEAR(fiscal_1_y_a!A13), focus_primary!$2:$2, 0), 0) -> 4.25 | C13: =VLOOKUP($A13, focus_primary!$A:$AQ, MATCH(YEAR(A13)+1, focus_primary!$2:$2, 0), 0) -> 4.25 | D13: =(B13*(12-MONTH(A13))+C13*MONTH(A13))/12 -> 4.25 | E13: =MONTH(A13) -> 10 | F13: =IF(E13<4,3,IF(E13<7,6,IF(E13<10,9,12))) -> 12 | G13: =YEAR(A13) -> 2006
... A4789: =focus_primary!A4790 -> 45945 | B4789: =VLOOKUP($A4789, focus_primary!$A:$AQ, MATCH(YEAR(fiscal_1_y_a!A4789), focus_primary!$2:$2, 0), 0) -> -0.5001 | C4789: =VLOOKUP($A4789, focus_primary!$A:$AQ, MATCH(YEAR(A4789)+1, focus_primary!$2:$2, 0), 0) -> -0.6 | D4789: =(B4789*(12-MONTH(A4789))+C4789*MONTH(A4789))/12 -> -0.58335 | E4789: =MONTH(A4789) -> 10 | F4789: =IF(E4789<4,3,IF(E4789<7,6,IF(E4789<10,9,12))) -> 12 | G4789: =YEAR(A4789) -> 2025
F4790: =IF(E4790<4,3,IF(E4790<7,6,IF(E4790<10,9,12))) -> 3
F4791: =IF(E4791<4,3,IF(E4791<7,6,IF(E4791<10,9,12))) -> 3
F4792: =IF(E4792<4,3,IF(E4792<7,6,IF(E4792<10,9,12))) -> 3
F4793: =IF(E4793<4,3,IF(E4793<7,6,IF(E4793<10,9,12))) -> 3
F4794: =IF(E4794<4,3,IF(E4794<7,6,IF(E4794<10,9,12))) -> 3
F4795: =IF(E4795<4,3,IF(E4795<7,6,IF(E4795<10,9,12))) -> 3
F4796: =IF(E4796<4,3,IF(E4796<7,6,IF(E4796<10,9,12))) -> 3
F4797: =IF(E4797<4,3,IF(E4797<7,6,IF(E4797<10,9,12))) -> 3
F4798: =IF(E4798<4,3,IF(E4798<7,6,IF(E4798<10,9,12))) -> 3
F4799: =IF(E4799<4,3,IF(E4799<7,6,IF(E4799<10,9,12))) -> 3
F4800: =IF(E4800<4,3,IF(E4800<7,6,IF(E4800<10,9,12))) -> 3
F4801: =IF(E4801<4,3,IF(E4801<7,6,IF(E4801<10,9,12))) -> 3
... F5528: =IF(E5528<4,3,IF(E5528<7,6,IF(E5528<10,9,12))) -> 3

Sheet focus_dlsp
A1: Resultado primário - % do PIB - Mediana - Período de 21/09/2006 a 21/09/2016 - Base: Expectativas informadas nos últimos 30 dias
A2: Data | B2: 2006 | C2: 2007 | D2: 2008 | E2: 2009 | F2: 2010 | G2: 2011 | H2: 2012 | I2: 2013 | J2: 2014 | K2: 2015 | L2: 2016 | M2: 2017 | N2: 2018 | O2: 2019 | P2: 2020 | Q2: =P2+1 -> 2021 | R2: =Q2+1 -> 2022 | S2: =R2+1 -> 2023 | T2: =S2+1 -> 2024 | U2: =T2+1 -> 2025 | V2: =U2+1 -> 2026 | W2: =V2+1 -> 2027 | X2: =W2+1 -> 2028 | ... AD2: =AC2+1 -> 2034
A3: 38982 | B3: 50.4 | C3: 49.1 | D3: 47.2 | E3: 45.65 | F3: 43.95
A4: 38985 | B4: 50.4 | C4: 49.1 | D4: 47 | E4: 45.55 | F4: 43.8
A5: 38986 | B5: 50.4 | C5: 49.1 | D5: 47 | E5: 45.55 | F5: 43.8
A6: 38987 | B6: 50.35 | C6: 49.1 | D6: 47 | E6: 45.5 | F6: 43.7
A7: 38988 | B7: 50.35 | C7: 49.1 | D7: 47.1 | E7: 45.6 | F7: 43.9
A8: 38989 | B8: 50.35 | C8: 49.1 | D8: 47.2 | E8: 45.65 | F8: 43.9
A9: 38992 | B9: 50.3 | C9: 49.1 | D9: 47.2 | E9: 45.65 | F9: 43.8
A10: 38993 | B10: 50.3 | C10: 49.1 | D10: 47.2 | E10: 45.65 | F10: 43.8
A11: 38994 | B11: 50.3 | C11: 49.1 | D11: 47.2 | E11: 45.65 | F11: 43.8
A12: 38995 | B12: 50.3 | C12: 49.1 | D12: 47.1 | E12: 45.6 | F12: 43.7
A13: 38996 | B13: 50.4 | C13: 49.1 | D13: 47.2 | E13: 45.65 | F13: 43.8
A14: 38999 | B14: 50.35 | C14: 49.1 | D14: 47.4 | E14: 45.6 | F14: 43.7
... A90: 39112 | B90: 50 | C90: 48.8 | D90: 47 | E90: 45 | F90: 42.9
A91: 39113 | C91: 48.8 | D91: 47 | E91: 45.35 | F91: 43.5 | G91: 42
A92: 39114 | C92: 48.8 | D92: 47 | E92: 45.35 | F92: 43.5 | G92: 42
A93: 39115 | C93: 48.9 | D93: 47 | E93: 45.35 | F93: 43.5 | G93: 42
A94: 39118 | C94: 49 | D94: 47 | E94: 45.4 | F94: 44 | G94: 42
A95: 39119 | C95: 49 | D95: 47 | E95: 45.4 | F95: 44 | G95: 41.5
A96: 39120 | C96: 49 | D96: 47 | E96: 45.45 | F96: 44 | G96: 41
A97: 39121 | C97: 49 | D97: 47 | E97: 45.45 | F97: 44 | G97: 41
A98: 39122 | C98: 49 | D98: 47 | E98: 45.4 | F98: 44 | G98: 41
A99: 39125 | C99: 49 | D99: 47 | E99: 45.35 | F99: 43.75 | G99: 41
A100: 39126 | C100: 49 | D100: 47 | E100: 45.35 | F100: 43.75 | G100: 41
A101: 39127 | C101: 48.9 | D101: 47 | E101: 45.3 | F101: 43.75 | G101: 41
A102: 39128 | C102: 48.9 | D102: 47 | E102: 45.3 | F102: 43.75 | G102: 41
... A339: 39476 | C339: 43 | D339: 41.7 | E339: 39.5 | F339: 37.5 | G339: 36.6
A340: 39477 | D340: 41.8 | E340: 39.5 | F340: 37.5 | G340: 36.6
A341: 39478 | D341: 41.8 | E341: 39.65 | F341: 37.9 | G341: 36.5 | H341: 35
A342: 39479 | D342: 41.8 | E342: 40 | F342: 37.95 | G342: 36.6 | H342: 35
A343: 39484 | D343: 41.8 | E343: 40 | F343: 37.95 | G343: 36.6 | H343: 36
A344: 39485 | D344: 41.6 | E344: 39.65 | F344: 37.9 | G344: 36.5 | H344: 36
A345: 39486 | D345: 41.6 | E345: 39.7 | F345: 37.95 | G345: 36.6 | H345: 36
A346: 39489 | D346: 41.7 | E346: 40 | F346: 38 | G346: 36.8 | H346: 37
A347: 39490 | D347: 41.7 | E347: 40 | F347: 38 | G347: 36.8 | H347: 37.5
A348: 39491 | D348: 41.7 | E348: 40 | F348: 38 | G348: 37 | H348: 37.5
A349: 39492 | D349: 41.7 | E349: 40 | F349: 38 | G349: 37 | H349: 37.5
A350: 39493 | D350: 41.7 | E350: 39.65 | F350: 38 | G350: 37 | H350: 36.9
A351: 39496 | D351: 41.8 | E351: 39.7 | F351: 38.12 | G351: 37 | H351: 36.8
...

Sheet dlsp_1_y_a
B1: debt_current | C1: debt_ya | D1: change_ya | E1: month | F1: quart | G1: year
A2: =focus_dlsp!A3 -> 38982 | B2: =VLOOKUP($A2, focus_dlsp!$A:$AQ, MATCH(YEAR(dlsp_1_y_a!A2), focus_dlsp!$2:$2, 0), 0) -> 50.4 | C2: =VLOOKUP($A2, focus_dlsp!$A:$AQ, MATCH(YEAR(A2)+1, focus_dlsp!$2:$2, 0), 0) -> 49.1 | D2: =C2-B2 -> -1.3 | E2: =MONTH(A2) -> 9 | F2: =IF(E2<4,3,IF(E2<7,6,IF(E2<10,9,12))) -> 9 | G2: =YEAR(A2) -> 2006
A3: =focus_dlsp!A4 -> 38985 | B3: =VLOOKUP($A3, focus_dlsp!$A:$AQ, MATCH(YEAR(dlsp_1_y_a!A3), focus_dlsp!$2:$2, 0), 0) -> 50.4 | C3: =VLOOKUP($A3, focus_dlsp!$A:$AQ, MATCH(YEAR(A3)+1, focus_dlsp!$2:$2, 0), 0) -> 49.1 | D3: =C3-B3 -> -1.3 | E3: =MONTH(A3) -> 9 | F3: =IF(E3<4,3,IF(E3<7,6,IF(E3<10,9,12))) -> 9 | G3: =YEAR(A3) -> 2006
A4: =focus_dlsp!A5 -> 38986 | B4: =VLOOKUP($A4, focus_dlsp!$A:$AQ, MATCH(YEAR(dlsp_1_y_a!A4), focus_dlsp!$2:$2, 0), 0) -> 50.4 | C4: =VLOOKUP($A4, focus_dlsp!$A:$AQ, MATCH(YEAR(A4)+1, focus_dlsp!$2:$2, 0), 0) -> 49.1 | D4: =C4-B4 -> -1.3 | E4: =MONTH(A4) -> 9 | F4: =IF(E4<4,3,IF(E4<7,6,IF(E4<10,9,12))) -> 9 | G4: =YEAR(A4) -> 2006
A5: =focus_dlsp!A6 -> 38987 | B5: =VLOOKUP($A5, focus_dlsp!$A:$AQ, MATCH(YEAR(dlsp_1_y_a!A5), focus_dlsp!$2:$2, 0), 0) -> 50.35 | C5: =VLOOKUP($A5, focus_dlsp!$A:$AQ, MATCH(YEAR(A5)+1, focus_dlsp!$2:$2, 0), 0) -> 49.1 | D5: =C5-B5 -> -1.25 | E5: =MONTH(A5) -> 9 | F5: =IF(E5<4,3,IF(E5<7,6,IF(E5<10,9,12))) -> 9 | G5: =YEAR(A5) -> 2006
A6: =focus_dlsp!A7 -> 38988 | B6: =VLOOKUP($A6, focus_dlsp!$A:$AQ, MATCH(YEAR(dlsp_1_y_a!A6), focus_dlsp!$2:$2, 0), 0) -> 50.35 | C6: =VLOOKUP($A6, focus_dlsp!$A:$AQ, MATCH(YEAR(A6)+1, focus_dlsp!$2:$2, 0), 0) -> 49.1 | D6: =C6-B6 -> -1.25 | E6: =MONTH(A6) -> 9 | F6: =IF(E6<4,3,IF(E6<7,6,IF(E6<10,9,12))) -> 9 | G6: =YEAR(A6) -> 2006
A7: =focus_dlsp!A8 -> 38989 | B7: =VLOOKUP($A7, focus_dlsp!$A:$AQ, MATCH(YEAR(dlsp_1_y_a!A7), focus_dlsp!$2:$2, 0), 0) -> 50.35 | C7: =VLOOKUP($A7, focus_dlsp!$A:$AQ, MATCH(YEAR(A7)+1, focus_dlsp!$2:$2, 0), 0) -> 49.1 | D7: =C7-B7 -> -1.25 | E7: =MONTH(A7) -> 9 | F7: =IF(E7<4,3,IF(E7<7,6,IF(E7<10,9,12))) -> 9 | G7: =YEAR(A7) -> 2006
A8: =focus_dlsp!A9 -> 38992 | B8: =VLOOKUP($A8, focus_dlsp!$A:$AQ, MATCH(YEAR(dlsp_1_y_a!A8), focus_dlsp!$2:$2, 0), 0) -> 50.3 | C8: =VLOOKUP($A8, focus_dlsp!$A:$AQ, MATCH(YEAR(A8)+1, focus_dlsp!$2:$2, 0), 0) -> 49.1 | D8: =C8-B8 -> -1.2 | E8: =MONTH(A8) -> 10 | F8: =IF(E8<4,3,IF(E8<7,6,IF(E8<10,9,12))) -> 12 | G8: =YEAR(A8) -> 2006
A9: =focus_dlsp!A10 -> 38993 | B9: =VLOOKUP($A9, focus_dlsp!$A:$AQ, MATCH(YEAR(dlsp_1_y_a!A9), focus_dlsp!$2:$2, 0), 0) -> 50.3 | C9: =VLOOKUP($A9, focus_dlsp!$A:$AQ, MATCH(YEAR(A9)+1, focus_dlsp!$2:$2, 0), 0) -> 49.1 | D9: =C9-B9 -> -1.2 | E9: =MONTH(A9) -> 10 | F9: =IF(E9<4,3,IF(E9<7,6,IF(E9<10,9,12))) -> 12 | G9: =YEAR(A9) -> 2006
A10: =focus_dlsp!A11 -> 38994 | B10: =VLOOKUP($A10, focus_dlsp!$A:$AQ, MATCH(YEAR(dlsp_1_y_a!A10), focus_dlsp!$2:$2, 0), 0) -> 50.3 | C10: =VLOOKUP($A10, focus_dlsp!$A:$AQ, MATCH(YEAR(A10)+1, focus_dlsp!$2:$2, 0), 0) -> 49.1 | D10: =C10-B10 -> -1.2 | E10: =MONTH(A10) -> 10 | F10: =IF(E10<4,3,IF(E10<7,6,IF(E10<10,9,12))) -> 12 | G10: =YEAR(A10) -> 2006
A11: =focus_dlsp!A12 -> 38995 | B11: =VLOOKUP($A11, focus_dlsp!$A:$AQ, MATCH(YEAR(dlsp_1_y_a!A11), focus_dlsp!$2:$2, 0), 0) -> 50.3 | C11: =VLOOKUP($A11, focus_dlsp!$A:$AQ, MATCH(YEAR(A11)+1, focus_dlsp!$2:$2, 0), 0) -> 49.1 | D11: =C11-B11 -> -1.2 | E11: =MONTH(A11) -> 10 | F11: =IF(E11<4,3,IF(E11<7,6,IF(E11<10,9,12))) -> 12 | G11: =YEAR(A11) -> 2006
A12: =focus_dlsp!A13 -> 38996 | B12: =VLOOKUP($A12, focus_dlsp!$A:$AQ, MATCH(YEAR(dlsp_1_y_a!A12), focus_dlsp!$2:$2, 0), 0) -> 50.4 | C12: =VLOOKUP($A12, focus_dlsp!$A:$AQ, MATCH(YEAR(A12)+1, focus_dlsp!$2:$2, 0), 0) -> 49.1 | D12: =C12-B12 -> -1.3 | E12: =MONTH(A12) -> 10 | F12: =IF(E12<4,3,IF(E12<7,6,IF(E12<10,9,12))) -> 12 | G12: =YEAR(A12) -> 2006
A13: =focus_dlsp!A14 -> 38999 | B13: =VLOOKUP($A13, focus_dlsp!$A:$AQ, MATCH(YEAR(dlsp_1_y_a!A13), focus_dlsp!$2:$2, 0), 0) -> 50.35 | C13: =VLOOKUP($A13, focus_dlsp!$A:$AQ, MATCH(YEAR(A13)+1, focus_dlsp!$2:$2, 0), 0) -> 49.1 | D13: =C13-B13 -> -1.25 | E13: =MONTH(A13) -> 10 | F13: =IF(E13<4,3,IF(E13<7,6,IF(E13<10,9,12))) -> 12 | G13: =YEAR(A13) -> 2006
... A4789: =focus_dlsp!A4790 -> 45946 | B4789: =VLOOKUP($A4789, focus_dlsp!$A:$AQ, MATCH(YEAR(dlsp_1_y_a!A4789), focus_dlsp!$2:$2, 0), 0) -> 65.7849 | C4789: =VLOOKUP($A4789, focus_dlsp!$A:$AQ, MATCH(YEAR(A4789)+1, focus_dlsp!$2:$2, 0), 0) -> 70.08 | D4789: =C4789-B4789 -> 4.2951 | E4789: =MONTH(A4789) -> 10 | F4789: =IF(E4789<4,3,IF(E4789<7,6,IF(E4789<10,9,12))) -> 12 | G4789: =YEAR(A4789) -> 2025
F4790: =IF(E4790<4,3,IF(E4790<7,6,IF(E4790<10,9,12))) -> 3
F4791: =IF(E4791<4,3,IF(E4791<7,6,IF(E4791<10,9,12))) -> 3
F4792: =IF(E4792<4,3,IF(E4792<7,6,IF(E4792<10,9,12))) -> 3
F4793: =IF(E4793<4,3,IF(E4793<7,6,IF(E4793<10,9,12))) -> 3
F4794: =IF(E4794<4,3,IF(E4794<7,6,IF(E4794<10,9,12))) -> 3
F4795: =IF(E4795<4,3,IF(E4795<7,6,IF(E4795<10,9,12))) -> 3
F4796: =IF(E4796<4,3,IF(E4796<7,6,IF(E4796<10,9,12))) -> 3
F4797: =IF(E4797<4,3,IF(E4797<7,6,IF(E4797<10,9,12))) -> 3
F4798: =IF(E4798<4,3,IF(E4798<7,6,IF(E4798<10,9,12))) -> 3
F4799: =IF(E4799<4,3,IF(E4799<7,6,IF(E4799<10,9,12))) -> 3
F4800: =IF(E4800<4,3,IF(E4800<7,6,IF(E4800<10,9,12))) -> 3
F4801: =IF(E4801<4,3,IF(E4801<7,6,IF(E4801<10,9,12))) -> 3
... F5528: =IF(E5528<4,3,IF(E5528<7,6,IF(E5528<10,9,12))) -> 3

Sheet format
A1: date | B1: hiato_bcb | C1: us_rate_gap | D1: ipca_gap | E1: brl_reer_gap | F1: ipca_ya_gap | G1: embi_gap
A2: 37956 | B2: =quart!C2 -> -1.1 | C2: =quart!D2-quart!F2 -> -1.7416469 | D2: =VLOOKUP($A2, monthly!$A:$H, 5, 0) - VLOOKUP(YEAR(A2), annual!$A:$B, 2, 0) -> -0.36735353 | G2: =AVERAGEIFS(daily!$I:$I, daily!$E:$E, MONTH(A2), daily!$F:$F, YEAR(A2)) -> #N/A
A3: =EDATE(A2, 3) -> 38047 | B3: =quart!C3 -> -0.63 | C3: =quart!D3-quart!F3 -> -1.6593216 | D3: =VLOOKUP($A3, monthly!$A:$H, 5, 0) - VLOOKUP(YEAR(A3), annual!$A:$B, 2, 0) -> 0.30338547 | G3: =AVERAGEIFS(daily!$I:$I, daily!$E:$E, MONTH(A3), daily!$F:$F, YEAR(A3)) -> #N/A
A4: =EDATE(A3, 3) -> 38139 | B4: =quart!C4 -> -0.21 | C4: =quart!D4-quart!F4 -> -1.6318991 | D4: =VLOOKUP($A4, monthly!$A:$H, 5, 0) - VLOOKUP(YEAR(A4), annual!$A:$B, 2, 0) -> 1.7930381 | G4: =AVERAGEIFS(daily!$I:$I, daily!$E:$E, MONTH(A4), daily!$F:$F, YEAR(A4)) -> #N/A
A5: =EDATE(A4, 3) -> 38231 | B5: =quart!C5 -> 0.19 | C5: =quart!D5-quart!F5 -> -1.1283776 | D5: =VLOOKUP($A5, monthly!$A:$H, 5, 0) - VLOOKUP(YEAR(A5), annual!$A:$B, 2, 0) -> 4.6906406 | E5: =VLOOKUP($A5, monthly!$A:$I, 7, 0) -> 0.25147101 | G5: =AVERAGEIFS(daily!$I:$I, daily!$E:$E, MONTH(A5), daily!$F:$F, YEAR(A5)) -> #N/A
A6: =EDATE(A5, 3) -> 38322 | B6: =quart!C6 -> 0.46 | C6: =quart!D6-quart!F6 -> -0.67145733 | D6: =VLOOKUP($A6, monthly!$A:$H, 5, 0) - VLOOKUP(YEAR(A6), annual!$A:$B, 2, 0) -> 1.6571721 | E6: =VLOOKUP($A6, monthly!$A:$I, 7, 0) -> -4.4949645 | G6: =AVERAGEIFS(daily!$I:$I, daily!$E:$E, MONTH(A6), daily!$F:$F, YEAR(A6)) -> #N/A
A7: =EDATE(A6, 3) -> 38412 | B7: =quart!C7 -> 0.47 | C7: =quart!D7-quart!F7 -> -0.2618235 | D7: =VLOOKUP($A7, monthly!$A:$H, 5, 0) - VLOOKUP(YEAR(A7), annual!$A:$B, 2, 0) -> 1.0517365 | E7: =VLOOKUP($A7, monthly!$A:$I, 7, 0) -> -6.823571 | G7: =AVERAGEIFS(daily!$I:$I, daily!$E:$E, MONTH(A7), daily!$F:$F, YEAR(A7)) -> #N/A
A8: =EDATE(A7, 3) -> 38504 | B8: =quart!C8 -> 0.06 | C8: =quart!D8-quart!F8 -> 0.37744395 | D8: =VLOOKUP($A8, monthly!$A:$H, 5, 0) - VLOOKUP(YEAR(A8), annual!$A:$B, 2, 0) -> 1.7286805 | E8: =VLOOKUP($A8, monthly!$A:$I, 7, 0) -> -9.9297012 | G8: =AVERAGEIFS(daily!$I:$I, daily!$E:$E, MONTH(A8), daily!$F:$F, YEAR(A8)) -> #N/A
A9: =EDATE(A8, 3) -> 38596 | B9: =quart!C9 -> -0.34 | C9: =quart!D9-quart!F9 -> 0.94245304 | D9: =VLOOKUP($A9, monthly!$A:$H, 5, 0) - VLOOKUP(YEAR(A9), annual!$A:$B, 2, 0) -> 0.72947445 | E9: =VLOOKUP($A9, monthly!$A:$I, 7, 0) -> -10.117867 | G9: =AVERAGEIFS(daily!$I:$I, daily!$E:$E, MONTH(A9), daily!$F:$F, YEAR(A9)) -> #N/A
A10: =EDATE(A9, 3) -> 38687 | B10: =quart!C10 -> -0.4 | C10: =quart!D10-quart!F10 -> 1.4118799 | D10: =VLOOKUP($A10, monthly!$A:$H, 5, 0) - VLOOKUP(YEAR(A10), annual!$A:$B, 2, 0) -> 1.2574246 | E10: =VLOOKUP($A10, monthly!$A:$I, 7, 0) -> -9.6597776 | G10: =AVERAGEIFS(daily!$I:$I, daily!$E:$E, MONTH(A10), daily!$F:$F, YEAR(A10)) -> #N/A
A11: =EDATE(A10, 3) -> 38777 | B11: =quart!C11 -> -0.34 | C11: =quart!D11-quart!F11 -> 1.7507723 | D11: =VLOOKUP($A11, monthly!$A:$H, 5, 0) - VLOOKUP(YEAR(A11), annual!$A:$B, 2, 0) -> -0.41061597 | E11: =VLOOKUP($A11, monthly!$A:$I, 7, 0) -> -6.4404276 | G11: =AVERAGEIFS(daily!$I:$I, daily!$E:$E, MONTH(A11), daily!$F:$F, YEAR(A11)) -> -6.4206349
A12: =EDATE(A11, 3) -> 38869 | B12: =quart!C12 -> -0.3 | C12: =quart!D12-quart!F12 -> 2.2269862 | D12: =VLOOKUP($A12, monthly!$A:$H, 5, 0) - VLOOKUP(YEAR(A12), annual!$A:$B, 2, 0) -> -3.3923829 | E12: =VLOOKUP($A12, monthly!$A:$I, 7, 0) -> -1.4305522 | G12: =AVERAGEIFS(daily!$I:$I, daily!$E:$E, MONTH(A12), daily!$F:$F, YEAR(A12)) -> 2.2103825
A13: =EDATE(A12, 3) -> 38961 | B13: =quart!C13 -> -0.15 | C13: =quart!D13-quart!F13 -> 2.7330618 | D13: =VLOOKUP($A13, monthly!$A:$H, 5, 0) - VLOOKUP(YEAR(A13), annual!$A:$B, 2, 0) -> -0.60399065 | E13: =VLOOKUP($A13, monthly!$A:$I, 7, 0) -> 0.6899111 | F13: =AVERAGEIFS(focus_ipca!$C:$C, focus_ipca!$E:$E, MONTH(A13), focus_ipca!$F:$F, YEAR(A13)) - VLOOKUP(YEAR(A13), annual!$A:$B, 2, 0) -> -0.37142857 | G13: =AVERAGEIFS(daily!$I:$I, daily!$E:$E, MONTH(A13), daily!$F:$F, YEAR(A13)) -> -1.7044271
A14: =EDATE(A13, 3) -> 39052 | B14: =quart!C14 -> 0.01 | C14: =quart!D14-quart!F14 -> 2.6993916 | D14: =VLOOKUP($A14, monthly!$A:$H, 5, 0) - VLOOKUP(YEAR(A14), annual!$A:$B, 2, 0) -> -0.99117333 | E14: =VLOOKUP($A14, monthly!$A:$I, 7, 0) -> 0.018607798 | F14: =AVERAGEIFS(focus_ipca!$C:$C, focus_ipca!$E:$E, MONTH(A14), focus_ipca!$F:$F, YEAR(A14)) - VLOOKUP(YEAR(A14), annual!$A:$B, 2, 0) -> -0.39327869 | G14: =AVERAGEIFS(daily!$I:$I, daily!$E:$E, MONTH(A14), daily!$F:$F, YEAR(A14)) -> -3.7322404
A15: =EDATE(A14, 3) -> 39142 | B15: =quart!C15 -> 0.31 | C15: =quart!D15-quart!F15 -> 2.6960578 | D15: =VLOOKUP($A15, monthly!$A:$H, 5, 0) - VLOOKUP(YEAR(A15), annual!$A:$B, 2, 0) -> -1.154413 | E15: =VLOOKUP($A15, monthly!$A:$I, 7, 0) -> -1.8098973 | F15: =AVERAGEIFS(focus_ipca!$C:$C, focus_ipca!$E:$E, MONTH(A15), focus_ipca!$F:$F, YEAR(A15)) - VLOOKUP(YEAR(A15), annual!$A:$B, 2, 0) -> -0.60145161 | G15: =AVERAGEIFS(daily!$I:$I, daily!$E:$E, MONTH(A15), daily!$F:$F, YEAR(A15)) -> -2.0860215
A16: =EDATE(A15, 3) -> 39234 | B16: =quart!C16 -> 0.59 | C16: =quart!D16-quart!F16 -> 2.7613061 | D16: =VLOOKUP($A16, monthly!$A:$H, 5, 0) - VLOOKUP(YEAR(A16), annual!$A:$B, 2, 0) -> -0.48568239 | E16: =VLOOKUP($A16, monthly!$A:$I, 7, 0) -> -4.5041942 | F16: =AVERAGEIFS(focus_ipca!$C:$C, focus_ipca!$E:$E, MONTH(A16), focus_ipca!$F:$F, YEAR(A16)) - VLOOKUP(YEAR(A16), annual!$A:$B, 2, 0) -> -1.0001613 | G16: =AVERAGEIFS(daily!$I:$I, daily!$E:$E, MONTH(A16), daily!$F:$F, YEAR(A16)) -> -1.8951613
A17: =EDATE(A16, 3) -> 39326 | B17: =quart!C17 -> 0.91 | C17: =quart!D17-quart!F17 -> 2.5636889 | D17: =VLOOKUP($A17, monthly!$A:$H, 5, 0) - VLOOKUP(YEAR(A17), annual!$A:$B, 2, 0) -> 1.2315152 | E17: =VLOOKUP($A17, monthly!$A:$I, 7, 0) -> -4.3795041 | F17: =AVERAGEIFS(focus_ipca!$C:$C, focus_ipca!$E:$E, MONTH(A17), focus_ipca!$F:$F, YEAR(A17)) - VLOOKUP(YEAR(A17), annual!$A:$B, 2, 0) -> -0.82875 | G17: =AVERAGEIFS(daily!$I:$I, daily!$E:$E, MONTH(A17), daily!$F:$F, YEAR(A17)) -> 1.9869792
A18: =EDATE(A17, 3) -> 39417 | B18: =quart!C18 -> 1.22 | C18: =quart!D18-quart!F18 -> 1.8924142 | D18: =VLOOKUP($A18, monthly!$A:$H, 5, 0) - VLOOKUP(YEAR(A18), annual!$A:$B, 2, 0) -> 0.25314702 | E18: =VLOOKUP($A18, monthly!$A:$I, 7, 0) -> -5.5602144 | F18: =AVERAGEIFS(focus_ipca!$C:$C, focus_ipca!$E:$E, MONTH(A18), focus_ipca!$F:$F, YEAR(A18)) - VLOOKUP(YEAR(A18), annual!$A:$B, 2, 0) -> -0.54451613 | G18: =AVERAGEIFS(daily!$I:$I, daily!$E:$E, MONTH(A18), daily!$F:$F, YEAR(A18)) -> 3.358871
A19: =EDATE(A18, 3) -> 39508 | B19: =quart!C19 -> 1.38 | C19: =quart!D19-quart!F19 -> 0.86194882 | D19: =VLOOKUP($A19, monthly!$A:$H, 5, 0) - VLOOKUP(YEAR(A19), annual!$A:$B, 2, 0) -> -0.077585205 | E19: =VLOOKUP($A19, monthly!$A:$I, 7, 0) -> -3.1574204 | F19: =AVERAGEIFS(focus_ipca!$C:$C, focus_ipca!$E:$E, MONTH(A19), focus_ipca!$F:$F, YEAR(A19)) - VLOOKUP(YEAR(A19), annual!$A:$B, 2, 0) -> -0.2147541 | G19: =AVERAGEIFS(daily!$I:$I, daily!$E:$E, MONTH(A19), daily!$F:$F, YEAR(A19)) -> 6.0614754
A20: =EDATE(A19, 3) -> 39600 | B20: =quart!C20 -> 1.62 | C20: =quart!D20-quart!F20 -> -0.2205006 | D20: =VLOOKUP($A20, monthly!$A:$H, 5, 0) - VLOOKUP(YEAR(A20), annual!$A:$B, 2, 0) -> 4.9036549 | E20: =VLOOKUP($A20, monthly!$A:$I, 7, 0) -> -3.009326 | F20: =AVERAGEIFS(focus_ipca!$C:$C, focus_ipca!$E:$E, MONTH(A20), focus_ipca!$F:$F, YEAR(A20)) - VLOOKUP(YEAR(A20), annual!$A:$B, 2, 0) -> 0.16435484 | G20: =AVERAGEIFS(daily!$I:$I, daily!$E:$E, MONTH(A20), daily!$F:$F, YEAR(A20)) -> -6.0819892
A21: =EDATE(A20, 3) -> 39692 | B21: =quart!C21 -> 1.42 | C21: =quart!D21-quart!F21 -> -0.10010087 | D21: =VLOOKUP($A21, monthly!$A:$H, 5, 0) - VLOOKUP(YEAR(A21), annual!$A:$B, 2, 0) -> 1.9925452 | E21: =VLOOKUP($A21, monthly!$A:$I, 7, 0) -> -2.1044672 | F21: =AVERAGEIFS(focus_ipca!$C:$C, focus_ipca!$E:$E, MONTH(A21), focus_ipca!$F:$F, YEAR(A21)) - VLOOKUP(YEAR(A21), annual!$A:$B, 2, 0) -> 0.77863636 | G21: =AVERAGEIFS(daily!$I:$I, daily!$E:$E, MONTH(A21), daily!$F:$F, YEAR(A21)) -> 8.1060606
A22: =EDATE(A21, 3) -> 39783 | B22: =quart!C22 -> -0.49 | C22: =quart!D22-quart!F22 -> -0.63420789 | D22: =VLOOKUP($A22, monthly!$A:$H, 5, 0) - VLOOKUP(YEAR(A22), annual!$A:$B, 2, 0) -> -1.1159654 | E22: =VLOOKUP($A22, monthly!$A:$I, 7, 0) -> 15.456538 | F22: =AVERAGEIFS(focus_ipca!$C:$C, focus_ipca!$E:$E, MONTH(A22), focus_ipca!$F:$F, YEAR(A22)) - VLOOKUP(YEAR(A22), annual!$A:$B, 2, 0) -> 0.75646154 | G22: =AVERAGEIFS(daily!$I:$I, daily!$E:$E, MONTH(A22), daily!$F:$F, YEAR(A22)) -> 10.935897
A23: =EDATE(A22, 3) -> 39873 | B23: =quart!C23 -> -1.82 | C23: =quart!D23-quart!F23 -> -0.64832809 | D23: =VLOOKUP($A23, monthly!$A:$H, 5, 0) - VLOOKUP(YEAR(A23), annual!$A:$B, 2, 0) -> -1.237647 | E23: =VLOOKUP($A23, monthly!$A:$I, 7, 0) -> 7.7000849 | F23: =AVERAGEIFS(focus_ipca!$C:$C, focus_ipca!$E:$E, MONTH(A23), focus_ipca!$F:$F, YEAR(A23)) - VLOOKUP(YEAR(A23), annual!$A:$B, 2, 0) -> 0.093114754 | G23: =AVERAGEIFS(daily!$I:$I, daily!$E:$E, MONTH(A23), daily!$F:$F, YEAR(A23)) -> -1.5819672
A24: =EDATE(A23, 3) -> 39965 | B24: =quart!C24 -> -1.86 | C24: =quart!D24-quart!F24 -> -0.70151327 | D24: =VLOOKUP($A24, monthly!$A:$H, 5, 0) - VLOOKUP(YEAR(A24), annual!$A:$B, 2, 0) -> 1.6072389 | E24: =VLOOKUP($A24, monthly!$A:$I, 7, 0) -> -3.3299357 | F24: =AVERAGEIFS(focus_ipca!$C:$C, focus_ipca!$E:$E, MONTH(A24), focus_ipca!$F:$F, YEAR(A24)) - VLOOKUP(YEAR(A24), annual!$A:$B, 2, 0) -> -0.40098361 | G24: =AVERAGEIFS(daily!$I:$I, daily!$E:$E, MONTH(A24), daily!$F:$F, YEAR(A24)) -> -11.67623
... A84: =EDATE(A83, 3) -> 45444 | B84: =quart!C84 -> 0.01 | C84: =quart!D84-quart!F84 -> 4.4722045 | D84: =VLOOKUP($A84, monthly!$A:$H, 5, 0) - VLOOKUP(YEAR(A84), annual!$A:$B, 2, 0) -> 2.0140816 | E84: =VLOOKUP($A84, monthly!$A:$I, 7, 0) -> 2.9300541 | F84: =AVERAGEIFS(focus_ipca!$C:$C, focus_ipca!$E:$E, MONTH(A84), focus_ipca!$F:$F, YEAR(A84)) - VLOOKUP(YEAR(A84), annual!$A:$B, 2, 0) -> 0.57988571 | G84: =AVERAGEIFS(daily!$I:$I, daily!$E:$E, MONTH(A84), daily!$F:$F, YEAR(A84)) -> 2.6058201
